Workbook

Sheet Summary
A1: p_tier2 wide-frame extraction audit
A2: Deduplicated clinical/biomedical RAG systems from Amugongo (70 studies) plus He (33 named systems), with primary-paper corrections and explicit ambiguity scenarios.
A3: Comparator prevalence | B3: 0.175
A5: Scenario | B5: n | C5: Tier-2 k | D5: Raw prevalence | E5: Jeffreys alpha | F5: Jeffreys beta | G5: Posterior mean | H5: 95% CrI lower | I5: 95% CrI upper | J5: Pr(p < 0.175) | K5: Exact one-sided P | M5: Scenario | N5: Observed prevalence | O5: Comparator 0.175
A6: Primary deduplicated set | B6: =COUNTIF(Analysis_Set!$J$2:$J$61,"Y") | C6: =COUNTIFS(Analysis_Set!$J$2:$J$61,"Y",Analysis_Set!$F$2:$F$61,"Tier 2") | D6: =C6/B6 | E6: =C6+0.5 | F6: =B6-C6+0.5 | G6: =E6/(E6+F6) | H6: =BETA.INV(0.025,E6,F6) | I6: =BETA.INV(0.975,E6,F6) | J6: =BETA.DIST($B$3,E6,F6,TRUE) | K6: =BINOM.DIST(C6,B6,$B$3,TRUE) | M6: Primary | N6: =D6 | O6: 0.175
A7: Package-level expanded set | B7: =COUNTIF(Analysis_Set!$K$2:$K$61,"Y") | C7: =COUNTIFS(Analysis_Set!$K$2:$K$61,"Y",Analysis_Set!$G$2:$G$61,"Tier 2") | D7: =C7/B7 | E7: =C7+0.5 | F7: =B7-C7+0.5 | G7: =E7/(E7+F7) | H7: =BETA.INV(0.025,E7,F7) | I7: =BETA.INV(0.975,E7,F7) | J7: =BETA.DIST($B$3,E7,F7,TRUE) | K7: =BINOM.DIST(C7,B7,$B$3,TRUE) | M7: Expanded | N7: =D7 | O7: 0.175
A8: Adversarial ambiguity set | B8: =COUNTIF(Analysis_Set!$L$2:$L$61,"Y") | C8: =COUNTIFS(Analysis_Set!$L$2:$L$61,"Y",Analysis_Set!$H$2:$H$61,"Tier 2") | D8: =C8/B8 | E8: =C8+0.5 | F8: =B8-C8+0.5 | G8: =E8/(E8+F8) | H8: =BETA.INV(0.025,E8,F8) | I8: =BETA.INV(0.975,E8,F8) | J8: =BETA.DIST($B$3,E8,F8,TRUE) | K8: =BINOM.DIST(C8,B8,$B$3,TRUE) | M8: Adversarial | N8: =D8 | O8: 0.175
A11: Interpretation and cautions
A12: Primary set | B12: 55 unique systems with a named encoder family/model/service sufficient for Tier classification after deduplication. It contains 2 Tier-2 cases: KG-RAG (definite PubMedBERT) and Chat-Orthopedist (MPNet; exact checkpoint remains a sensitivity issue).
A13: Expanded set | B13: Adds RAG-HPO (FastEmbed package) and SurgeryLLM (GPT4All embedding package) as probable Tier 1. Both papers omit the exact embedding checkpoint.
A14: Adversarial set | B14: Adds CLEAR, WeiseEule, and MEDRAG and deliberately assigns every unresolved or mixed encoder case against the hypothesis, producing 5/60. This is not the preferred estimator; it is a robustness bound.
A15: Statistical reading | B15: The Jeffreys posterior is Beta(k+0.5, n-k+0.5). The one-sided exact P column tests H0: p=0.175 against p<0.175. A two-sided Wilson interval is slightly more conservative and may still touch 0.175 in the 5/60 stress test.
A16: Population limitation | B16: Published systems are not a random sample of production deployments. Commercial systems and undisclosed local implementations may use different encoder choices. The result is an evidence-based literature prior, not a registry prevalence estimate.

Sheet Analysis_Set
A1: Canonical ID | B1: System | C1: Source frame | D1: Source row | E1: Reported operational encoder/retriever | F1: Core tier | G1: Expanded tier | H1: Adversarial tier | I1: Confidence | J1: Core include | K1: Expanded include | L1: Adversarial include | M1: Audit note | N1: Review/source URL | O1: Primary source URL | P1: Coding provenance
A2: A01 | B2: Abdullahi / CliniqIR | C2: Amugongo | D2: 1 | E2: ClinicalBERT, PubMedBERT, SciBERT, SapBERT, CODER, MedCPT; selected MedCPT + BM25 | F2: Tier 1 | G2: Tier 1 | H2: Tier 1 | I2: High | J2: Y | K2: Y | L2: Y | M2: Operational dense component is MedCPT, a retrieval-trained biomedical encoder. | N2: https://journals.plos.org/digitalhealth/article?id=10.1371/journal.pdig.0000877
A3: A04 | B3: Aratesh | C3: Amugongo | D3: 4 | E3: OpenAI text-embedding-ada-002 | F3: Tier 1 | G3: Tier 1 | H3: Tier 1 | I3: Moderate | J3: Y | K3: Y | L3: Y | M3: Dedicated embedding service used for retrieval. | N3: https://journals.plos.org/digitalhealth/article?id=10.1371/journal.pdig.0000877
A4: A05 | B4: Azimi / RAP | C4: Amugongo | D4: 5 | E4: Amazon Titan Text Embeddings V2 | F4: Tier 1 | G4: Tier 1 | H4: Tier 1 | I4: Moderate | J4: Y | K4: Y | L4: Y | M4: Dedicated embedding service used for retrieval. | N4: https://journals.plos.org/digitalhealth/article?id=10.1371/journal.pdig.0000877
A5: A06 | B5: Benfenati | C5: Amugongo | D5: 6 | E5: GTE | F5: Tier 1 | G5: Tier 1 | H5: Tier 1 | I5: Moderate | J5: Y | K5: Y | L5: Y | M5: GTE is trained as a general text retriever/embedding model. | N5: https://journals.plos.org/digitalhealth/article?id=10.1371/journal.pdig.0000877
A6: A07 | B6: Bora & Cuayáhuitl | C6: Amugongo | D6: 7 | E6: gtr-t5-large | F6: Tier 1 | G6: Tier 1 | H6: Tier 1 | I6: Moderate | J6: Y | K6: Y | L6: Y | M6: GTR is trained for text retrieval. | N6: https://journals.plos.org/digitalhealth/article?id=10.1371/journal.pdig.0000877
A7: A09 | B7: Chen [22] | C7: Amugongo | D7: 9 | E7: all-MiniLM-L6-v2 | F7: Tier 1 | G7: Tier 1 | H7: Tier 1 | I7: Moderate | J7: Y | K7: Y | L7: Y | M7: Sentence-transformer checkpoint trained for similarity/retrieval. | N7: https://journals.plos.org/digitalhealth/article?id=10.1371/journal.pdig.0000877
A8: A12 | B8: Fukushima / JGCLLM | C8: Amugongo | D8: 12 | E8: GLuCoSE-base-ja | F8: Tier 1 | G8: Tier 1 | H8: Tier 1 | I8: Moderate | J8: Y | K8: Y | L8: Y | M8: Contrastive sentence-embedding model. | N8: https://journals.plos.org/digitalhealth/article?id=10.1371/journal.pdig.0000877
A9: A14 | B9: Garcia | C9: Amugongo | D9: 14 | E9: BGE | F9: Tier 1 | G9: Tier 1 | H9: Tier 1 | I9: Moderate | J9: Y | K9: Y | L9: Y | M9: BGE is retrieval/contrastive-trained. | N9: https://journals.plos.org/digitalhealth/article?id=10.1371/journal.pdig.0000877
A10: A15 | B10: Ge | C10: Amugongo | D10: 15 | E10: OpenAI text-embedding-ada-002 | F10: Tier 1 | G10: Tier 1 | H10: Tier 1 | I10: Moderate | J10: Y | K10: Y | L10: Y | M10: Dedicated embedding service. | N10: https://journals.plos.org/digitalhealth/article?id=10.1371/journal.pdig.0000877
A11: A17 | B11: Guo / RALL | C11: Amugongo | D11: 17 | E11: Dense Passage Retriever with fine-tuned query encoder | F11: Tier 1 | G11: Tier 1 | H11: Tier 1 | I11: High | J11: Y | K11: Y | L11: Y | M11: Primary paper uses DPR and fine-tunes the query encoder; not bare BERT. | N11: https://journals.plos.org/digitalhealth/article?id=10.1371/journal.pdig.0000877 | O11: https://doi.org/10.1016/j.jbi.2023.104580
A12: A18 | B12: Jeong / Self-BioRAG | C12: Amugongo | D12: 18 | E12: MedCPT | F12: Tier 1 | G12: Tier 1 | H12: Tier 1 | I12: High | J12: Y | K12: Y | L12: Y | M12: MedCPT is contrastively trained on PubMed search logs. | N12: https://journals.plos.org/digitalhealth/article?id=10.1371/journal.pdig.0000877 | O12: https://doi.org/10.1093/bioinformatics/btae238
A13: A19 | B13: Jia | C13: Amugongo | D13: 19 | E13: BGE | F13: Tier 1 | G13: Tier 1 | H13: Tier 1 | I13: Moderate | J13: Y | K13: Y | L13: Y | M13: Retrieval-trained embedding model. | N13: https://journals.plos.org/digitalhealth/article?id=10.1371/journal.pdig.0000877
A14: A20 | B14: Jiang | C14: Amugongo | D14: 20 | E14: BGE | F14: Tier 1 | G14: Tier 1 | H14: Tier 1 | I14: Moderate | J14: Y | K14: Y | L14: Y | M14: Retrieval-trained embedding model. | N14: https://journals.plos.org/digitalhealth/article?id=10.1371/journal.pdig.0000877
A15: A21 | B15: Jin [69] | C15: Amugongo | D15: 21 | E15: OpenAI text-embedding-ada-002 | F15: Tier 1 | G15: Tier 1 | H15: Tier 1 | I15: Moderate | J15: Y | K15: Y | L15: Y | M15: Dedicated embedding service. | N15: https://journals.plos.org/digitalhealth/article?id=10.1371/journal.pdig.0000877
A16: A23 | B16: Hou | C16: Amugongo | D16: 23 | E16: OpenAI text-embedding-3-small | F16: Tier 1 | G16: Tier 1 | H16: Tier 1 | I16: Moderate | J16: Y | K16: Y | L16: Y | M16: Dedicated embedding service. | N16: https://journals.plos.org/digitalhealth/article?id=10.1371/journal.pdig.0000877
A17: A25 | B17: Ke [73] | C17: Amugongo | D17: 25 | E17: OpenAI text-embedding-ada-002 | F17: Tier 1 | G17: Tier 1 | H17: Tier 1 | I17: Moderate | J17: Y | K17: Y | L17: Y | M17: Dedicated embedding service. | N17: https://journals.plos.org/digitalhealth/article?id=10.1371/journal.pdig.0000877
A18: A27 | B18: Klang | C18: Amugongo | D18: 27 | E18: GIST-large-embedding-v0 | F18: Tier 1 | G18: Tier 1 | H18: Tier 1 | I18: Moderate | J18: Y | K18: Y | L18: Y | M18: GISTEmbed is trained as a text-embedding/retrieval model. | N18: https://journals.plos.org/digitalhealth/article?id=10.1371/journal.pdig.0000877
A19: A29 | B19: Lee | C19: Amugongo | D19: 29 | E19: OpenAI embedding models | F19: Tier 1 | G19: Tier 1 | H19: Tier 1 | I19: Moderate | J19: Y | K19: Y | L19: Y | M19: Dedicated embedding APIs. | N19: https://journals.plos.org/digitalhealth/article?id=10.1371/journal.pdig.0000877
A20: A31 | B20: Li [80] | C20: Amugongo | D20: 31 | E20: OpenAI text-embedding-3-small | F20: Tier 1 | G20: Tier 1 | H20: Tier 1 | I20: Moderate | J20: Y | K20: Y | L20: Y | M20: Dedicated embedding service. | N20: https://journals.plos.org/digitalhealth/article?id=10.1371/journal.pdig.0000877
A21: A32 | B21: Long / ChatENT | C21: Amugongo | D21: 32 | E21: OpenAI text-embedding-ada-002 | F21: Tier 1 | G21: Tier 1 | H21: Tier 1 | I21: Moderate | J21: Y | K21: Y | L21: Y | M21: Dedicated embedding service. | N21: https://journals.plos.org/digitalhealth/article?id=10.1371/journal.pdig.0000877 | O21: https://doi.org/10.1002/ohn.864
A22: A35 | B22: Luo | C22: Amugongo | D22: 35 | E22: SBERT | F22: Tier 1 | G22: Tier 1 | H22: Tier 1 | I22: Moderate | J22: Y | K22: Y | L22: Y | M22: Sentence-BERT is explicitly trained for sentence similarity. | N22: https://journals.plos.org/digitalhealth/article?id=10.1371/journal.pdig.0000877
A23: A39 | B23: Murugan | C23: Amugongo | D23: 39 | E23: OpenAI text-embedding-ada-002 | F23: Tier 1 | G23: Tier 1 | H23: Tier 1 | I23: Moderate | J23: Y | K23: Y | L23: Y | M23: Dedicated embedding service. | N23: https://journals.plos.org/digitalhealth/article?id=10.1371/journal.pdig.0000877
A24: A40 | B24: Neupane | C24: Amugongo | D24: 40 | E24: OpenAI text-embedding-ada-002 | F24: Tier 1 | G24: Tier 1 | H24: Tier 1 | I24: Moderate | J24: Y | K24: Y | L24: Y | M24: Dedicated embedding service. | N24: https://journals.plos.org/digitalhealth/article?id=10.1371/journal.pdig.0000877
A25: A41 | B25: Ong [88] | C25: Amugongo | D25: 41 | E25: OpenAI text-embedding-ada-002 + bge-small-en-v1.5 | F25: Tier 1 | G25: Tier 1 | H25: Tier 1 | I25: Moderate | J25: Y | K25: Y | L25: Y | M25: Both dense components are dedicated retrieval embeddings. | N25: https://journals.plos.org/digitalhealth/article?id=10.1371/journal.pdig.0000877
A26: A42 | B26: Painter | C26: Amugongo | D26: 42 | E26: OpenAI text-embedding-ada-002 | F26: Tier 1 | G26: Tier 1 | H26: Tier 1 | I26: Moderate | J26: Y | K26: Y | L26: Y | M26: Dedicated embedding service. | N26: https://journals.plos.org/digitalhealth/article?id=10.1371/journal.pdig.0000877
A27: A43 | B27: Pang | C27: Amugongo | D27: 43 | E27: Fine-tuned embedding model | F27: Tier 1 | G27: Tier 1 | H27: Tier 1 | I27: Moderate | J27: Y | K27: Y | L27: Y | M27: Operational embedding was explicitly fine-tuned for the task. | N27: https://journals.plos.org/digitalhealth/article?id=10.1371/journal.pdig.0000877
A28: A44 | B28: Parmanto | C28: Amugongo | D28: 44 | E28: BGE | F28: Tier 1 | G28: Tier 1 | H28: Tier 1 | I28: Moderate | J28: Y | K28: Y | L28: Y | M28: Retrieval-trained embedding model. | N28: https://journals.plos.org/digitalhealth/article?id=10.1371/journal.pdig.0000877
A29: A45 | B29: Quidwai | C29: Amugongo | D29: 45 | E29: bge-small-en-v1.5 | F29: Tier 1 | G29: Tier 1 | H29: Tier 1 | I29: Moderate | J29: Y | K29: Y | L29: Y | M29: Retrieval-trained embedding checkpoint. | N29: https://journals.plos.org/digitalhealth/article?id=10.1371/journal.pdig.0000877
A30: A46 | B30: Ranjit | C30: Amugongo | D30: 46 | E30: ALBEF | F30: Tier 1 | G30: Tier 1 | H30: Tier 1 | I30: Moderate | J30: Y | K30: Y | L30: Y | M30: Contrastively trained multimodal retrieval model. | N30: https://journals.plos.org/digitalhealth/article?id=10.1371/journal.pdig.0000877
A31: A47 | B31: Rau | C31: Amugongo | D31: 47 | E31: OpenAI text-embedding-ada-002 | F31: Tier 1 | G31: Tier 1 | H31: Tier 1 | I31: Moderate | J31: Y | K31: Y | L31: Y | M31: Dedicated embedding service. | N31: https://journals.plos.org/digitalhealth/article?id=10.1371/journal.pdig.0000877
A32: A48 | B32: Russe | C32: Amugongo | D32: 48 | E32: OpenAI text-embedding-ada-002 | F32: Tier 1 | G32: Tier 1 | H32: Tier 1 | I32: Moderate | J32: Y | K32: Y | L32: Y | M32: Dedicated embedding service. | N32: https://journals.plos.org/digitalhealth/article?id=10.1371/journal.pdig.0000877
A33: A50 | B33: Shi / Chat-Orthopedist | C33: Amugongo | D33: 50 | E33: MPNet; primary article cites the original MPNet base-model paper | F33: Tier 2 | G33: Tier 2 | H33: Tier 2 | I33: High | J33: Y | K33: Y | L33: Y | M33: Tier 2 on the basis of the representation actually extracted. The primary article reports extraction of the [CLS] representation (Section 3.2, doi:10.1145/3584371.3612956) and identifies MPNet by reference to the original MPNet model (Song et al.) rather than to a retrieval-trained sentence-embedding checkpoint. On the reported implementation the retrieval representation was therefore not shown to have been calibrated by a retrieval-specific objective. Membership follows from the extracted representation, not from the training label. | N33: https://journals.plos.org/digitalhealth/article?id=10.1371/journal.pdig.0000877 | O33: https://doi.org/10.1145/3584371.3612956 | P33: SUPERSEDED RATIONALE: 'No retrieval/similarity-tuned checkpoint is identified. Recoded as ambiguous in sensitivity notes.' This basis is invalid: citing the base-model paper is the standard citation for the contrastively fine-tuned sentence-transformer checkpoint, so the absence of a named similarity-tuned checkpoint does not follow. Tier 2 coding is unchanged; only the basis is corrected.
A34: A51 | B34: Soman / KG-RAG | C34: Amugongo | D34: 51 | E34: PubMedBERT selected for context embeddings | F34: Tier 2 | G34: Tier 2 | H34: Tier 2 | I34: High | J34: Y | K34: Y | L34: Y | M34: Primary paper selected base PubMedBERT for semantic context pruning after model comparison. | N34: https://journals.plos.org/digitalhealth/article?id=10.1371/journal.pdig.0000877 | O34: https://doi.org/10.1093/bioinformatics/btae560
A35: A52 | B35: So | C35: Amugongo | D35: 52 | E35: OpenAI text-embedding-ada-002 | F35: Tier 1 | G35: Tier 1 | H35: Tier 1 | I35: Moderate | J35: Y | K35: Y | L35: Y | M35: Dedicated embedding service. | N35: https://journals.plos.org/digitalhealth/article?id=10.1371/journal.pdig.0000877
A36: A53 | B36: Soong | C36: Amugongo | D36: 53 | E36: OpenAI text-embedding-ada-002 | F36: Tier 1 | G36: Tier 1 | H36: Tier 1 | I36: Moderate | J36: Y | K36: Y | L36: Y | M36: Dedicated embedding service. | N36: https://journals.plos.org/digitalhealth/article?id=10.1371/journal.pdig.0000877 | O36: https://arxiv.org/abs/2305.17116
A37: A54 | B37: Steybe / GuideGPT | C37: Amugongo | D37: 54 | E37: OpenAI text-embedding-ada-002 | F37: Tier 1 | G37: Tier 1 | H37: Tier 1 | I37: Moderate | J37: Y | K37: Y | L37: Y | M37: Dedicated embedding service. | N37: https://journals.plos.org/digitalhealth/article?id=10.1371/journal.pdig.0000877 | O37: https://doi.org/10.1016/j.jcms.2024.12.009
A38: A56 | B38: Unlu / RECTIFIER | C38: Amugongo | D38: 56 | E38: OpenAI text-embedding-ada-002 | F38: Tier 1 | G38: Tier 1 | H38: Tier 1 | I38: Moderate | J38: Y | K38: Y | L38: Y | M38: Dedicated embedding service. | N38: https://journals.plos.org/digitalhealth/article?id=10.1371/journal.pdig.0000877 | O38: https://doi.org/10.1101/2024.02.08.24302376
A39: A59 | B39: Wang [106] | C39: Amugongo | D39: 59 | E39: ColBERT | F39: Tier 1 | G39: Tier 1 | H39: Tier 1 | I39: Moderate | J39: Y | K39: Y | L39: Y | M39: ColBERT is explicitly trained for information retrieval. | N39: https://journals.plos.org/digitalhealth/article?id=10.1371/journal.pdig.0000877
A40: A60 | B40: Wang [107] / RISE | C40: Amugongo | D40: 60 | E40: OpenAI text-embedding-ada-002 | F40: Tier 1 | G40: Tier 1 | H40: Tier 1 | I40: Moderate | J40: Y | K40: Y | L40: Y | M40: Dedicated embedding service. | N40: https://journals.plos.org/digitalhealth/article?id=10.1371/journal.pdig.0000877 | O40: https://doi.org/10.2196/58041
...

Sheet Amugongo70
A1: Review row | B1: System / lead author | C1: Reported encoder/retriever | D1: Tier classification | E1: Primary-analysis status | F1: Audit rationale | G1: Primary verification status | H1: Review URL | I1: Primary URL
A2: 1 | B2: Abdullahi / CliniqIR | C2: ClinicalBERT, PubMedBERT, SciBERT, SapBERT, CODER, MedCPT; selected MedCPT + BM25 | D2: Tier 1 | E2: Include | F2: Operational dense component is MedCPT, a retrieval-trained biomedical encoder. | G2: Primary selection verified from system description | H2: https://journals.plos.org/digitalhealth/article?id=10.1371/journal.pdig.0000877
A3: 2 | B3: Alkhalaf | C3: Not reported | D3: Unclassifiable | E3: Exclude | F3: No operational dense encoder disclosed. | G3: Not recovered | H3: https://journals.plos.org/digitalhealth/article?id=10.1371/journal.pdig.0000877
A4: 3 | B4: Al Ghadban | C4: Not reported | D4: Unclassifiable | E4: Exclude | F4: No operational dense encoder disclosed. | G4: Not recovered | H4: https://journals.plos.org/digitalhealth/article?id=10.1371/journal.pdig.0000877
A5: 4 | B5: Aratesh | C5: OpenAI text-embedding-ada-002 | D5: Tier 1 | E5: Include | F5: Dedicated embedding service used for retrieval. | G5: Review extraction | H5: https://journals.plos.org/digitalhealth/article?id=10.1371/journal.pdig.0000877
A6: 5 | B6: Azimi / RAP | C6: Amazon Titan Text Embeddings V2 | D6: Tier 1 | E6: Include | F6: Dedicated embedding service used for retrieval. | G6: Review extraction | H6: https://journals.plos.org/digitalhealth/article?id=10.1371/journal.pdig.0000877
A7: 6 | B7: Benfenati | C7: GTE | D7: Tier 1 | E7: Include | F7: GTE is trained as a general text retriever/embedding model. | G7: Review extraction | H7: https://journals.plos.org/digitalhealth/article?id=10.1371/journal.pdig.0000877
A8: 7 | B8: Bora & Cuayáhuitl | C8: gtr-t5-large | D8: Tier 1 | E8: Include | F8: GTR is trained for text retrieval. | G8: Review extraction | H8: https://journals.plos.org/digitalhealth/article?id=10.1371/journal.pdig.0000877
A9: 8 | B9: Chen [21] | C9: Not reported | D9: Unclassifiable | E9: Exclude | F9: No operational dense encoder disclosed. | G9: Not recovered | H9: https://journals.plos.org/digitalhealth/article?id=10.1371/journal.pdig.0000877
A10: 9 | B10: Chen [22] | C10: all-MiniLM-L6-v2 | D10: Tier 1 | E10: Include | F10: Sentence-transformer checkpoint trained for similarity/retrieval. | G10: Review extraction | H10: https://journals.plos.org/digitalhealth/article?id=10.1371/journal.pdig.0000877
A11: 10 | B11: Das | C11: Not reported | D11: Unclassifiable | E11: Exclude | F11: No operational dense encoder disclosed. | G11: Not recovered | H11: https://journals.plos.org/digitalhealth/article?id=10.1371/journal.pdig.0000877
A12: 11 | B12: Duan | C12: NER / knowledge-graph retrieval | D12: Not applicable | E12: Exclude | F12: No dense document encoder in the deployed retrieval path. | G12: Review extraction | H12: https://journals.plos.org/digitalhealth/article?id=10.1371/journal.pdig.0000877
A13: 12 | B13: Fukushima / JGCLLM | C13: GLuCoSE-base-ja | D13: Tier 1 | E13: Include | F13: Contrastive sentence-embedding model. | G13: Review extraction | H13: https://journals.plos.org/digitalhealth/article?id=10.1371/journal.pdig.0000877
... A17: 16 | B17: Griewing | C17: Not reported | D17: Unclassifiable | E17: Exclude | F17: No operational dense encoder disclosed. | G17: Not recovered | H17: https://journals.plos.org/digitalhealth/article?id=10.1371/journal.pdig.0000877
A18: 17 | B18: Guo / RALL | C18: Dense Passage Retriever with fine-tuned query encoder | D18: Tier 1 | E18: Include | F18: Primary paper uses DPR and fine-tunes the query encoder; not bare BERT. | G18: Primary verified | H18: https://journals.plos.org/digitalhealth/article?id=10.1371/journal.pdig.0000877 | I18: https://doi.org/10.1016/j.jbi.2023.104580
A19: 18 | B19: Jeong / Self-BioRAG | C19: MedCPT | D19: Tier 1 | E19: Include | F19: MedCPT is contrastively trained on PubMed search logs. | G19: Primary/system verified | H19: https://journals.plos.org/digitalhealth/article?id=10.1371/journal.pdig.0000877 | I19: https://doi.org/10.1093/bioinformatics/btae238
A20: 19 | B20: Jia | C20: BGE | D20: Tier 1 | E20: Include | F20: Retrieval-trained embedding model. | G20: Review extraction | H20: https://journals.plos.org/digitalhealth/article?id=10.1371/journal.pdig.0000877
A21: 20 | B21: Jiang | C21: BGE | D21: Tier 1 | E21: Include | F21: Retrieval-trained embedding model. | G21: Review extraction | H21: https://journals.plos.org/digitalhealth/article?id=10.1371/journal.pdig.0000877
A22: 21 | B22: Jin [69] | C22: OpenAI text-embedding-ada-002 | D22: Tier 1 | E22: Include | F22: Dedicated embedding service. | G22: Review extraction | H22: https://journals.plos.org/digitalhealth/article?id=10.1371/journal.pdig.0000877
A23: 22 | B23: Jin / GeneGPT | C23: Tool/API retrieval; no dense encoder | D23: Not applicable | E23: Exclude | F23: Tool-use system without an operational dense encoder. | G23: Review extraction | H23: https://journals.plos.org/digitalhealth/article?id=10.1371/journal.pdig.0000877
A24: 23 | B24: Hou | C24: OpenAI text-embedding-3-small | D24: Tier 1 | E24: Include | F24: Dedicated embedding service. | G24: Review extraction | H24: https://journals.plos.org/digitalhealth/article?id=10.1371/journal.pdig.0000877
A25: 24 | B25: Kang | C25: None reported | D25: Unclassifiable | E25: Exclude | F25: No operational dense encoder disclosed. | G25: Not recovered | H25: https://journals.plos.org/digitalhealth/article?id=10.1371/journal.pdig.0000877
A26: 25 | B26: Ke [73] | C26: OpenAI text-embedding-ada-002 | D26: Tier 1 | E26: Include | F26: Dedicated embedding service. | G26: Review extraction | H26: https://journals.plos.org/digitalhealth/article?id=10.1371/journal.pdig.0000877
A27: 26 | B27: Ke [74] | C27: Not reported | D27: Unclassifiable | E27: Exclude | F27: No operational dense encoder disclosed. | G27: Not recovered | H27: https://journals.plos.org/digitalhealth/article?id=10.1371/journal.pdig.0000877
A28: 27 | B28: Klang | C28: GIST-large-embedding-v0 | D28: Tier 1 | E28: Include | F28: GISTEmbed is trained as a text-embedding/retrieval model. | G28: Review extraction | H28: https://journals.plos.org/digitalhealth/article?id=10.1371/journal.pdig.0000877
A29: 28 | B29: Kresevic | C29: Not reported | D29: Unclassifiable | E29: Exclude | F29: No operational dense encoder disclosed. | G29: Not recovered | H29: https://journals.plos.org/digitalhealth/article?id=10.1371/journal.pdig.0000877
A30: 29 | B30: Lee | C30: OpenAI embedding models | D30: Tier 1 | E30: Include | F30: Dedicated embedding APIs. | G30: Review extraction | H30: https://journals.plos.org/digitalhealth/article?id=10.1371/journal.pdig.0000877
A31: 30 | B31: Li [79] | C31: Not reported | D31: Unclassifiable | E31: Exclude | F31: No operational dense encoder disclosed. | G31: Not recovered | H31: https://journals.plos.org/digitalhealth/article?id=10.1371/journal.pdig.0000877
A32: 31 | B32: Li [80] | C32: OpenAI text-embedding-3-small | D32: Tier 1 | E32: Include | F32: Dedicated embedding service. | G32: Review extraction | H32: https://journals.plos.org/digitalhealth/article?id=10.1371/journal.pdig.0000877
A33: 32 | B33: Long / ChatENT | C33: OpenAI text-embedding-ada-002 | D33: Tier 1 | E33: Include | F33: Dedicated embedding service. | G33: Review extraction | H33: https://journals.plos.org/digitalhealth/article?id=10.1371/journal.pdig.0000877 | I33: https://doi.org/10.1002/ohn.864
A34: 33 | B34: Long / Bailicai | C34: No embedding reported | D34: Unclassifiable | E34: Exclude | F34: Generator named, but operational dense encoder not disclosed. | G34: Not recovered | H34: https://journals.plos.org/digitalhealth/article?id=10.1371/journal.pdig.0000877
A35: 34 | B35: Lozano | C35: Online search | D35: Not applicable | E35: Exclude | F35: Search-engine retrieval rather than dense encoder deployment. | G35: Review extraction | H35: https://journals.plos.org/digitalhealth/article?id=10.1371/journal.pdig.0000877
A36: 35 | B36: Luo | C36: SBERT | D36: Tier 1 | E36: Include | F36: Sentence-BERT is explicitly trained for sentence similarity. | G36: Review extraction | H36: https://journals.plos.org/digitalhealth/article?id=10.1371/journal.pdig.0000877
A37: 36 | B37: Markey | C37: Online search / not reported | D37: Not applicable | E37: Exclude | F37: No classifiable dense encoder. | G37: Review extraction | H37: https://journals.plos.org/digitalhealth/article?id=10.1371/journal.pdig.0000877
A38: 37 | B38: Mashatian | C38: Not reported | D38: Unclassifiable | E38: Exclude | F38: No operational dense encoder disclosed. | G38: Not recovered | H38: https://journals.plos.org/digitalhealth/article?id=10.1371/journal.pdig.0000877
A39: 38 | B39: Matsumoto | C39: Knowledge graph / graph of thoughts | D39: Not applicable | E39: Exclude | F39: Graph retrieval rather than dense document embedding. | G39: Review extraction | H39: https://journals.plos.org/digitalhealth/article?id=10.1371/journal.pdig.0000877
A40: 39 | B40: Murugan | C40: OpenAI text-embedding-ada-002 | D40: Tier 1 | E40: Include | F40: Dedicated embedding service. | G40: Review extraction | H40: https://journals.plos.org/digitalhealth/article?id=10.1371/journal.pdig.0000877
A41: 40 | B41: Neupane | C41: OpenAI text-embedding-ada-002 | D41: Tier 1 | E41: Include | F41: Dedicated embedding service. | G41: Review extraction | H41: https://journals.plos.org/digitalhealth/article?id=10.1371/journal.pdig.0000877
A42: 41 | B42: Ong [88] | C42: OpenAI text-embedding-ada-002 + bge-small-en-v1.5 | D42: Tier 1 | E42: Include | F42: Both dense components are dedicated retrieval embeddings. | G42: Review extraction | H42: https://journals.plos.org/digitalhealth/article?id=10.1371/journal.pdig.0000877
A43: 42 | B43: Painter | C43: OpenAI text-embedding-ada-002 | D43: Tier 1 | E43: Include | F43: Dedicated embedding service. | G43: Review extraction | H43: https://journals.plos.org/digitalhealth/article?id=10.1371/journal.pdig.0000877
...

Sheet He33
A1: Survey row | B1: System | C1: Reported encoder/retriever | D1: Tier classification | E1: Dedup / analysis status | F1: Audit rationale | G1: Verification | H1: Survey URL | I1: Primary URL
A2: 1 | B2: AskFDALabel | C2: Sentence Transformer | D2: Tier 1 | E2: Unique - core | F2: Survey identifies Sentence Transformer/SBERT family; exact checkpoint not disclosed. | G2: Family-level classification | H2: https://arxiv.org/abs/2505.01146 | I2: https://doi.org/10.1016/j.yrtph.2024.105613
A3: 2 | B3: CaLM | C3: BGE embedding | D3: Tier 1 | E3: Unique - core | F3: BGE is retrieval/contrastive-trained. | G3: Survey extraction | H3: https://arxiv.org/abs/2505.01146
A4: 3 | B4: RAG-HPO | C4: FastEmbed library | D4: Unresolved; probable Tier 1 | E4: Unique - package sensitivity | F4: Library named but checkpoint omitted; FastEmbed ordinarily serves dedicated retrieval embeddings. | G4: Primary not fully recoverable | H4: https://arxiv.org/abs/2505.01146 | I4: https://doi.org/10.1101/2024.12.01.24318253
A5: 4 | B5: RALL | C5: DPR with fine-tuned query encoder | D5: Tier 1 | E5: Duplicate - Amugongo 17 | F5: Same Guo lay-language-generation paper. | G5: Primary verified | H5: https://arxiv.org/abs/2505.01146 | I5: https://doi.org/10.1016/j.jbi.2023.104580
A6: 5 | B6: RT (Retrieving and Thinking) | C6: BERT embeddings | D6: Tier 2 | E6: Exclude - scope | F6: Few-shot NER example retrieval, not document retrieval feeding a generative clinical RAG output. | G6: Primary scope checked | H6: https://arxiv.org/abs/2505.01146 | I6: https://doi.org/10.1093/jamia/ocae095
A7: 6 | B7: RAG-GPT | C7: BGE embedding | D7: Tier 1 | E7: Unique - core | F7: BGE is retrieval/contrastive-trained. | G7: Survey extraction | H7: https://arxiv.org/abs/2505.01146 | I7: https://doi.org/10.1038/s41598-024-81052-3
A8: 7 | B8: GNQA | C8: HNSW graph | D8: Unclassifiable | E8: Exclude | F8: HNSW is an ANN index, not an encoder. | G8: Survey extraction | H8: https://arxiv.org/abs/2505.01146
A9: 8 | B9: Klang et al. | C9: GIST Large Embedding | D9: Tier 1 | E9: Duplicate - Amugongo 27 | F9: Same ICD coding system. | G9: Survey dedup | H9: https://arxiv.org/abs/2505.01146
A10: 9 | B10: RAGPR | C10: SBERT embeddings | D10: Tier 1 | E10: Duplicate - Amugongo 69 | F10: Same personalized physician-recommendation paper. | G10: Primary/reference dedup | H10: https://arxiv.org/abs/2505.01146 | I10: https://doi.org/10.3389/fpubh.2025.1501408
A11: 10 | B11: JGCLLM | C11: GLuCoSE-base-ja | D11: Tier 1 | E11: Duplicate - Amugongo 12 | F11: Same Japanese genetic-counselling system. | G11: Survey dedup | H11: https://arxiv.org/abs/2505.01146 | I11: https://doi.org/10.2196/65047
A12: 11 | B12: DRAGON-AI | C12: OpenAI text embedding | D12: Tier 1 | E12: Unique - core | F12: Dedicated embedding service. | G12: Primary/reference checked | H12: https://arxiv.org/abs/2505.01146 | I12: https://doi.org/10.1186/s13326-024-00320-3
A13: 12 | B13: RISE | C13: OpenAI text embedding | D13: Tier 1 | E13: Duplicate - Amugongo 60 | F13: Same diabetes-education paper. | G13: Primary/reference dedup | H13: https://arxiv.org/abs/2505.01146 | I13: https://doi.org/10.2196/58041
A14: 13 | B14: Dual RAG | C14: UPstage API + OpenAI embedding | D14: Tier 1 | E14: Duplicate - Amugongo 29 | F14: Same dual-RAG diabetes implementation. | G14: Probable title/reference dedup | H14: https://arxiv.org/abs/2505.01146
A15: 14 | B15: FAVOR-GPT | C15: OpenAI text embedding | D15: Tier 1 | E15: Duplicate probable - Amugongo Li | F15: Whole-genome variant annotation system already represented by a Li row in Amugongo. | G15: Conservative dedup | H15: https://arxiv.org/abs/2505.01146 | I15: https://doi.org/10.1093/bioadv/vbae143
A16: 15 | B16: Endo-chat | C16: OpenAI text embedding | D16: Tier 1 | E16: Unique - core | F16: Dedicated embedding service. | G16: Primary/reference checked | H16: https://arxiv.org/abs/2505.01146 | I16: https://doi.org/10.3389/fmed.2024.1500258
A17: 16 | B17: ChatENT | C17: OpenAI text embedding | D17: Tier 1 | E17: Duplicate - Amugongo 32 | F17: Same ChatENT paper. | G17: Primary/reference dedup | H17: https://arxiv.org/abs/2505.01146 | I17: https://doi.org/10.1002/ohn.864
A18: 17 | B18: GuideGPT | C18: OpenAI text embedding | D18: Tier 1 | E18: Duplicate - Amugongo 54 | F18: Same Steybe MRONJ chatbot. | G18: Primary/reference dedup | H18: https://arxiv.org/abs/2505.01146 | I18: https://doi.org/10.1016/j.jcms.2024.12.009
A19: 18 | B19: RECTIFIER | C19: OpenAI text embedding | D19: Tier 1 | E19: Duplicate - Amugongo 56 | F19: Same clinical-trial screening paper. | G19: Primary/reference dedup | H19: https://arxiv.org/abs/2505.01146 | I19: https://doi.org/10.1101/2024.02.08.24302376
A20: 19 | B20: RAP | C20: Amazon Titan embeddings | D20: Tier 1 | E20: Duplicate - Amugongo 5 | F20: Same Azimi nutrition/RD examination implementation. | G20: Primary/reference dedup | H20: https://arxiv.org/abs/2505.01146 | I20: https://doi.org/10.1038/s41598-024-85003-w
A21: 20 | B21: InfectA-Chat | C21: OpenAI text embedding | D21: Tier 1 | E21: Unique - core | F21: Dedicated embedding service. | G21: Primary/reference checked | H21: https://arxiv.org/abs/2505.01146 | I21: https://doi.org/10.2196/63881
A22: 21 | B22: DCRAG | C22: OpenAI text embedding | D22: Tier 1 | E22: Exclude - nonclinical | F22: Plant phenotype application outside target population. | G22: Scope checked | H22: https://arxiv.org/abs/2505.01146
A23: 22 | B23: PM-Search | C23: BioBERT | D23: Tier 2 | E23: Exclude - retrieval only | F23: Biomedical literature retrieval without a generative RAG deployment. | G23: Scope checked | H23: https://arxiv.org/abs/2505.01146
A24: 23 | B24: LADER | C24: PubMedBERT-derived log-augmented retriever | D24: Tier 1 | E24: Exclude - retrieval only | F24: Retrieval-only system; additionally trained with search logs. | G24: Primary abstract checked | H24: https://arxiv.org/abs/2505.01146 | I24: https://doi.org/10.1145/3539618.3592005
A25: 24 | B25: CLEAR | C25: Entity selector: Bio+ClinicalBERT; chunk-embedding comparator: BGE | D25: Tier 2 / noncanonical | E25: Unique - adversarial sensitivity | F25: Primary system is entity-based RAG; BGE is the chunk-embedding baseline. Counted Tier2 only in adversarial sensitivity. | G25: Primary verified | H25: https://arxiv.org/abs/2505.01146 | I25: https://doi.org/10.1038/s41746-024-01377-1
A26: 25 | B26: KG-RAG | C26: PubMedBERT | D26: Tier 2 | E26: Duplicate - Amugongo 51 | F26: Same Soman KG-RAG system. | G26: Primary verified | H26: https://arxiv.org/abs/2505.01146 | I26: https://doi.org/10.1093/bioinformatics/btae560
A27: 26 | B27: WeiseEule | C27: MedCPT + BioBERT + BioGPT | D27: Mixed | E27: Unique - adversarial sensitivity | F27: Mixed set contains retrieval-trained and non-retrieval-trained encoders; no single selected encoder reported. | G27: Survey/primary-method ambiguity | H27: https://arxiv.org/abs/2505.01146 | I27: https://doi.org/10.1186/s12859-024-05902-7
A28: 27 | B28: BiomedRAG | C28: Tailored learned chunk scorer supervised by LLM | D28: Tier 1 | E28: Unique - core | F28: Primary paper trains an explicit retrieval scorer; survey label MedLLaMA refers to the broader architecture. | G28: Primary verified | H28: https://arxiv.org/abs/2505.01146 | I28: https://arxiv.org/abs/2405.00465
A29: 28 | B29: SurgeryLLM | C29: GPT4All embedding package with Chroma | D29: Unresolved; probable Tier 1 | E29: Unique - package sensitivity | F29: Primary paper names the embedding package but not the actual checkpoint. | G29: Primary verified at package level | H29: https://arxiv.org/abs/2505.01146 | I29: https://doi.org/10.1038/s41746-024-01391-3
A30: 29 | B30: Myers et al. | C30: LLM2Vec comparison arm | D30: Not applicable | E30: Exclude - comparison | F30: Comparison arm rather than selected deployment encoder. | G30: Survey scope | H30: https://arxiv.org/abs/2505.01146
A31: 30 | B31: Self-BioRAG | C31: MedCPT | D31: Tier 1 | E31: Duplicate - Amugongo 18 | F31: Same system. | G31: Dedup | H31: https://arxiv.org/abs/2505.01146
A32: 31 | B32: CliniqIR | C32: MedCPT + BM25 | D32: Tier 1 | E32: Duplicate - Amugongo 1 | F32: Same system. | G32: Dedup | H32: https://arxiv.org/abs/2505.01146
A33: 32 | B33: MEDRAG toolkit | C33: BM25 + SPECTER + Contriever + MedCPT | D33: Tier 1 | E33: Unique - adversarial sensitivity | F33: Toolkit rather than a single deployed clinical system; all named dense encoders are retrieval-trained. | G33: Included only to force broad n=60 stress test | H33: https://arxiv.org/abs/2505.01146 | I33: https://arxiv.org/abs/2402.13178
A34: 33 | B34: RAMIE | C34: MedCPT + Contriever + BMRetriever | D34: Tier 1 | E34: Unique - core | F34: All named dense retrievers have explicit retrieval training. | G34: Survey extraction | H34: https://arxiv.org/abs/2505.01146

Sheet Rules
A1: Extraction and classification rules
A3: Rule | B3: Operational definition | C3: Included examples | D3: Excluded/ambiguous examples | E3: Bias direction | F3: Reason
A4: Tier 1 | B4: Encoder or service explicitly trained for retrieval, ranking, sentence similarity, contrastive embedding, or a task-specific learned retriever. | C4: BGE, GTE, MedCPT, DPR, SBERT, GIST, ColBERT, OpenAI/Titan embedding APIs | D4: None | E4: Reduces estimated p_tier2 | F4: Whitening already-calibrated retrieval geometry is not the target intervention.
A5: Tier 2 | B5: Operational dense representation from a base language model without identified retrieval/similarity training. | C5: PubMedBERT in KG-RAG; MPNet in Chat-Orthopedist under main coding | D5: Exact checkpoint missing | E5: Increases estimated p_tier2 | F5: These are the model classes plausibly susceptible to post-hoc geometric correction.
A6: Population | B6: Unique clinical or biomedical system in which retrieved material is supplied to a generator or generative workflow. | C6: Clinical QA, decision support, report generation | D6: Retrieval-only search engines, NER example retrieval, nonclinical plant systems | E6: Avoids denominator inflation | F6: Matches the Paper 9 intervention population.
A7: Deduplication | B7: Same primary paper/system appearing in both reviews is counted once. | C7: RALL/Guo, KG-RAG/Soman, Self-BioRAG/Jeong | D7: Review rows retained on source sheets but not repeated in Analysis_Set | E7: Prevents false precision | F7: The 70 + 33 source rows are not 103 independent systems.
A8: Missing encoder | B8: Exclude from primary denominator when neither model family nor dedicated embedding service is identifiable. | C8: — | D8: NA, HNSW-only, vector DB only, unspecified embedding | E8: Could bias prevalence if disclosure is informative | F8: Missingness sensitivity must be discussed; it cannot be solved by guessing defaults.
A9: Adversarial scenario | B9: Include five broad/ambiguous systems and classify unresolved cases against the hypothesis. | C9: RAG-HPO, SurgeryLLM, CLEAR, WeiseEule, MEDRAG | D9: Not used as preferred estimate | E9: Raises p_tier2 | F9: Tests whether the conclusion p_tier2 < 0.175 survives deliberately unfavorable coding.
A10: Statistical model | B10: Jeffreys binomial posterior Beta(k+0.5,n-k+0.5); compare with p=0.175. | C10: Posterior mean and 95% CrI | D10: No claim of population representativeness | E10: Quantifies sampling uncertainty only | F10: Publication and disclosure selection remain structural limitations.
